Workbook

Sheet README
A1: HISAAB DO: Paisa Kahan Gaya? The money ledger, 2000–2026
A3: Facts as of | B3: September 2026 (the as-of month of the bank items behind the rows: 2026-09)
A4: Rows | B4: 389 measures, one per row on the Ledger sheet (2000–2026)
A5: By level | B5: Centre 128, State 261
A6: By mode | B6: Seedha Khaate Mein (distribution) 137, Rahat Kosh (relief) 95, Chunav Se Pehle (pre-election) 157
A7: Before a poll | B7: 164 rows name the election they preceded; 137 of them record the gap in days
A8: In the app | B8: https://occult-kranti.github.io/fact-duel/hisaab/#/money/ledger
A9: Corrections | B9: Report an error from the app's Rules & Sources page: https://occult-kranti.github.io/fact-duel/hisaab/#/rules
A11: About this file
A12: What it is | B12: One row per measure that handed out public money directly between 2000 and 2026: cash and in-kind transfers, relief funds and disaster money, and the budgets, bills and notifications announced before an election. For each: who announced or passed it, which party governed, the benefit, reach and cost, the poll it preceded with the gap in days and the official result, and what happened next.
A13: Sources | B13: Every row carries its own source: source_label ("Publisher — title (date)") and source_url, a page that was fetched and states the core fact. Each row is built from HISAAB DO question-bank items (bank_items), which were fact-checked against fetched pages under the edition's charter; the ledger adds no new research, and every number in a row appears in its own items. The lanes worked from Union budget speeches and Economic Surveys (indiabudget.gov.in), PRS Legislative Research budget analyses, Finance Commission reports, the Rajya Sabha Standing Committee on Home Affairs (261st report, Disaster Management), PIB and PMO releases, CAG audits (read through reports of their tabling), court records (Indian Kanoon, LiveLaw), peer-reviewed studies, and news reports. Election results are the official results as the bank states them (ECI figures, through the cited outlet).
A14: Source hosts | B14: Most cited first: indianexpress.com 61, thehindu.com 46, timesofindia.indiatimes.com 44, indiabudget.gov.in 31, newindianexpress.com 27, frontline.thehindu.com 24, prsindia.org 22, hindustantimes.com 15, pmindia.gov.in 11, indiatoday.in 10, rediff.com 9, business-standard.com 8; 51 hosts in all.
A15: How to read it | B15: governing_party is who governed at that level when the measure came (NDA or UPA for the Centre); it is not a verdict, and the counts reflect what the bank covers, not which party spends more. Costs carry their own qualifiers and are not comparable across rows: do not sum them. The two package rows (Karnataka's five guarantees, Telangana's six) overlap the rows of their parts. A "yes" in launched_is_approximate means "active by", not "launched in".
A16: Timing, not cause | B16: days_before_poll and poll_result record when a measure came and what the official result was. They do not show that the measure changed the result, and no row claims what caused an election result. Words such as "freebie" or "revdi" appear only where a row quotes whoever said them.
A17: Sheets | B17: Ledger: the rows (filter and sort freely). By year: measures per launch year by mode and level, as COUNTIFS formulas over the Ledger sheet. README: this sheet.
A19: Column | B19: Meaning
A20: id | B20: Stable id of the measure: <state code>-<measure>-<year>.
A21: launched | B21: When the measure was announced, launched or first paid, as the bank dates it (YYYY or YYYY-MM).
A22: launched_is_approximate | B22: "yes" when the bank gives no launch date: "launched" is then the earliest date it gives. Read it as "active by".
A23: year | B23: The launch year.
A24: measure | B24: Short name of the measure.
... A45: source_url | B45: A link to the fetched page that states the core fact.

Sheet Ledger
A1: id | B1: launched | C1: launched_is_approximate | D1: year | E1: measure | F1: mode | G1: mode_name | H1: level | I1: state_code | J1: state | K1: governing_party | L1: enacted_by | M1: benefit | N1: reach | O1: cost | P1: poll | Q1: poll_month | R1: days_before_poll | S1: poll_result | T1: outcome | U1: package_overlaps_parts | V1: tags | W1: bank_items | X1: play_links | Y1: source_label | Z1: source_url
A2: gj-drought-relief-2000 | B2: 2000 | D2: 2000 | E2: Drought relief works (Gujarat) | F2: relief | G2: Rahat Kosh (the relief fund) | H2: State | I2: GJ | J2: Gujarat | K2: BJP | M2: ₹10 a day per adult (₹5 per child) on relief works, capped at ₹1,000 a month per family | N2: Five lakh people on 2,500 works; 9,421 villages declared drought-hit | T2: Frontline judged the cash relief insufficient; 2.5 crore people were affected and kharif losses put at ₹4,250 crore. | V2: relief | W2: hrf201 | X2: https://occult-kranti.github.io/fact-duel/hisaab/#/q/hrf201 | Y2: Frontline — Gujarat's thirst (13 May 2000) | Z2: https://frontline.thehindu.com/environment/article30253968.ece
A3: in-11th-fc-calamity-relief-fund-2000 | B3: 2000 | D3: 2000 | E3: Calamity Relief Fund, 2000–05 (11th Finance Commission) | F3: relief | G3: Rahat Kosh (the relief fund) | H3: Centre | I3: IN | J3: India-wide (Centre) | K3: NDA | M3: State calamity funds for cyclone, drought, earthquake, fire, flood and hailstorm, paid 75:25 by Centre and states | O3: ₹11,007.59 crore over five years (Centre ₹8,255.69 crore) | T3: About 75% bigger than the 1995–2000 fund; UP’s five-year share was ₹987 crore and Goa’s under ₹7 crore. | V3: relief | W3: hrf200 | X3: https://occult-kranti.github.io/fact-duel/hisaab/#/q/hrf200 | Y3: Finance Commission of India — Report of the Eleventh Finance Commission, ch. IX and Annexure IX.1 (2000) | Z3: https://fincomindia.nic.in/asset/doc/commission-reports/11th-FC/11threport.pdf
A4: in-nccf-2000 | B4: 2000 | D4: 2000 | E4: National Calamity Contingency Fund | F4: relief | G4: Rahat Kosh (the relief fund) | H4: Centre | I4: IN | J4: India-wide (Centre) | K4: NDA | M4: A national fund for severe calamities, replacing an exhausted one, refilled by a surcharge on central taxes | O4: ₹500 crore initial corpus | T4: Sent ₹500 crore to quake-hit Gujarat in 2001 and ₹1,018 crore for the 2002 drought; folded into the NDRF from 2010-11. | V4: relief | W4: hrf001 | X4: https://occult-kranti.github.io/fact-duel/hisaab/#/q/hrf001 | Y4: Rajya Sabha Standing Committee on Home Affairs — 261st Report: Disaster Management (presented 7 Aug 2026), para 2.13.4 | Z4: https://bucketapi.rajyasabha.digital/public-bucket/uploads/committee/2026_08_21_committee_3339_976_6a881941b462a.pdf
A5: kl-treasury-curbs-2001 | B5: 2000 | C5: yes | D5: 2000 | E5: Treasury curbs before the 2001 poll (Kerala) | F5: pre-election | G5: Chunav Se Pehle (before the vote) | H5: State | I5: KL | J5: Kerala | K5: LDF | M5: Curbs on even routine treasury transactions for six months, with debt near ₹21,000 crore | P5: Kerala Assembly 2001 | Q5: 2001-05 | S5: UDF won 99 of 140 seats; LDF 40 | T5: The UDF won 99 of 140 seats; the LDF fell to 40. | V5: pre-election | W5: hpe200 | X5: https://occult-kranti.github.io/fact-duel/hisaab/#/q/hpe200 | Y5: Frontline — A record of sorts (26 May 2001) | Z5: https://frontline.thehindu.com/politics/article30250696.ece
A6: in-janashree-bima-2000 | B6: 2000-02 | D6: 2000 | E6: Janashree Bima Yojana | F6: distribution | G6: Seedha Khaate Mein (straight into the account) | H6: Centre | I6: IN | J6: India-wide (Centre) | K6: NDA | L6: Yashwant Sinha (Union Finance Minister, BJP) | M6: Group insurance for the poor: ₹20,000 natural death, ₹50,000 accidental death; BPL members pay half | N6: 289.94 lakh lives covered by Dec 2012 | T6: Merged into the Aam Admi Bima Yojana (launched 2007). | V6: distribution | W6: hdb400 | X6: https://occult-kranti.github.io/fact-duel/hisaab/#/q/hdb400 | Y6: Ministry of Finance — Union Budget 2000-01 speech, Part A: Social Security for the Poor (2000) | Z6: https://www.indiabudget.gov.in/budget_archive/ub2000-01/bs/bsa5.htm
A7: in-antyodaya-anna-yojana-2000 | B7: 2000-12 | D7: 2000 | E7: Antyodaya Anna Yojana | F7: distribution | G7: Seedha Khaate Mein (straight into the account) | H7: Centre | I7: IN | J7: India-wide (Centre) | K7: NDA | L7: Atal Bihari Vajpayee (Prime Minister, BJP) | M7: Wheat at ₹2 and rice at ₹3 a kg for the poorest families; 35 kg a month from April 2002 | N7: 1 crore families at launch; 2.5 crore by May 2005 | T7: The flat 35 kg carried into the 2013 food law; a 2026 draft bill would switch to 7 kg a person, capped at 35 kg. | V7: distribution | W7: hdb001; hdb045 | X7: https://occult-kranti.github.io/fact-duel/hisaab/#/q/hdb001 https://occult-kranti.github.io/fact-duel/hisaab/#/q/hdb045 | Y7: Dept of Food & Public Distribution, NFSA portal — Public Distribution System: Antyodaya Anna Yojana (accessed Sep 2026) | Z7: https://nfsa.gov.in/portal/PDS_page
A8: od-cyclone-shelters-2001 | B8: 2001 | D8: 2001 | E8: Cyclone shelters after the 1999 super cyclone | F8: relief | G8: Rahat Kosh (the relief fund) | H8: State | I8: OD | J8: Odisha | K8: BJD | M8: Cyclone shelters for coastal Orissa: 512 needed, money allocated for 240 | T8: Only 23 stood in March 2001 and work on 489 had not begun (Frontline). | V8: relief | W8: hrf101 | X8: https://occult-kranti.github.io/fact-duel/hisaab/#/q/hrf101 | Y8: Frontline — Some lessons from Orissa (3 Mar 2001) | Z8: https://frontline.thehindu.com/other/article30249961.ece
A9: od-mission-shakti-2001 | B9: 2001 | D9: 2001 | E9: Mission Shakti (Odisha) | F9: distribution | G9: Seedha Khaate Mein (straight into the account) | H9: State | I9: OD | J9: Odisha | K9: BJD | L9: Naveen Patnaik (Chief Minister, Odisha, BJD) | M9: Women’s self-help groups: 0% loans up to ₹3 lakh, interest subvention | N9: Over six lakh SHGs, 70 lakh women | O9: About ₹200 crore a year in interest subvention | T9: Bank credit to SHGs rose from ₹1,036 crore (2016-17) to ₹4,190 crore (2020-21). | V9: distribution | W9: hdb312 | X9: https://occult-kranti.github.io/fact-duel/hisaab/#/q/hdb312 | Y9: The Hindu — Behind the BJD's electoral successes in Odisha are women SHGs (17 Oct 2022) | Z9: https://www.thehindu.com/news/national/other-states/behind-the-bjds-electoral-successes-in-odisha-are-women-shgs/article66022675.ece
A10: gj-kutch-earthquake-doles-2001 | B10: 2001-01 | D10: 2001 | E10: Kutch earthquake cash doles | F10: relief | G10: Rahat Kosh (the relief fund) | H10: State | I10: GJ | J10: Gujarat | K10: BJP | L10: Keshubhai Patel (Chief Minister, Gujarat, BJP) | M10: Cash doles for survivors and a promised room for each of eight lakh uprooted families | T10: India Today counted 11 orders on doles in 10 days; Frontline called the relief the government’s most striking failure. Patel was replaced in Oct 2001. | V10: relief | W10: hrf100 | X10: https://occult-kranti.github.io/fact-duel/hisaab/#/q/hrf100 | Y10: India Today — Leader in paralysis (5 Mar 2001) | Z10: https://www.indiatoday.in/magazine/states/story/20010305-gujarat-cm-keshubhai-patel-fitness-to-rule-grows-after-failure-to-provide-quake-relief-775615-2001-03-04
A11: in-nccd-2001 | B11: 2001-02 | D11: 2001 | E11: National Calamity Contingent Duty | F11: relief | G11: Rahat Kosh (the relief fund) | H11: Centre | I11: IN | J11: India-wide (Centre) | K11: NDA | L11: Yashwant Sinha (Union Finance Minister, BJP) | M11: A special excise levy on tobacco to refill the national calamity fund, plus a 2% surcharge for Gujarat quake relief | T11: Still on the books in 2026: Finance Bill 2026 raised its schedule rate on chewing tobacco from 25% to 60%. | V11: relief | W11: hrf002 | X11: https://occult-kranti.github.io/fact-duel/hisaab/#/q/hrf002 | Y11: indiabudget.gov.in — Memorandum explaining the provisions in the Finance Bill, 2026 (Feb 2026) | Z11: https://www.indiabudget.gov.in/doc/memo.pdf
A12: in-sgry-2001 | B12: 2001-09 | D12: 2001 | E12: Sampoorna Grameen Rozgar Yojana | F12: distribution | G12: Seedha Khaate Mein (straight into the account) | H12: Centre | I12: IN | J12: India-wide (Centre) | K12: NDA | L12: Atal Bihari Vajpayee (Prime Minister, BJP) | M12: Rural wage work paid partly in free grain, merging two earlier schemes | O12: 50 lakh tonnes of grain allocated for year one | T12: 30.6 lakh tonnes had been authorised for release by the 2002-03 budget; grain off-take rose sharply in the 2002 drought. | V12: distribution | W12: hdb401 | X12: https://occult-kranti.github.io/fact-duel/hisaab/#/q/hdb401 | Y12: Ministry of Finance — Union Budget 2002-03 speech, Part A (2002) | Z12: https://www.indiabudget.gov.in/budget_archive/ub2002-03/bs/speech_a.htm
A13: in-mid-day-meals-order-2001 | B13: 2001-11 | D13: 2001 | E13: Cooked mid-day meals ordered (PUCL case) | F13: distribution | G13: Seedha Khaate Mein (straight into the account) | H13: Centre | I13: IN | J13: India-wide (Centre) | K13: NDA | M13: Supreme Court directed every state to serve cooked mid-day meals in primary schools within six months | T13: Compliance lagged: in August 2002 Frontline reported Jharkhand had still not complied. | V13: distribution | W13: hdb002 | X13: https://occult-kranti.github.io/fact-duel/hisaab/#/q/hdb002 | Y13: Frontline — Starving still in Jharkhand (3 Aug 2002) | Z13: https://frontline.thehindu.com/other/article30245718.ece
A14: ap-drought-relief-rice-2002 | B14: 2002 | D14: 2002 | E14: Drought relief rice under SGRY (Andhra Pradesh) | F14: relief | G14: Rahat Kosh (the relief fund) | H14: State | I14: AP | J14: Andhra Pradesh | K14: TDP | M14: State sought 2.5 million tonnes of rice for drought relief work and ₹2,373.44 crore from the NCCF | N14: 1.38 crore farm labourers lost work (govt estimate) | T14: Only 0.5 million tonnes had been released by May 2003, Frontline reported. | V14: relief | W14: hrf102 | X14: https://occult-kranti.github.io/fact-duel/hisaab/#/q/hrf102 | Y14: Frontline — Elusive relief in Andhra Pradesh (23 May 2003) | Z14: https://frontline.thehindu.com/the-nation/article30217066.ece
A15: ga-dayanand-social-security-2002 | B15: 2002 | D15: 2002 | E15: Dayanand Social Security Scheme | F15: distribution | G15: Seedha Khaate Mein (straight into the account) | H15: State | I15: GA | J15: Goa | K15: BJP | L15: Manohar Parrikar (Chief Minister, Goa, BJP) | M15: Monthly pension for senior citizens (₹2,000 + ₹500 medical in 2026); ₹4,000 for eligible widows | N15: With Griha Aadhar, close to 2.5 lakh people | O15: ₹480 crore (2026-27 budget) | T15: In Sept 2026 the CM said it would rise by at least ₹500 a month; The Goan called it a ‘poll bonanza’ before 2027. | V15: distribution | W15: hdb200 | X15: https://occult-kranti.github.io/fact-duel/hisaab/#/q/hdb200 | Y15: The Goan — Another bonanza on cards: Govt to enhance DSSS, Griha Aadhar by Rs 500 (10 Sep 2026) | Z15: https://www.thegoan.net/goa-news/another-bonanza-on-cards-govt-to-enhance-dsss-griha-aadhar-by-rs-500/153962.html
A16: in-drought-relief-2002 | B16: 2002 | D16: 2002 | E16: Drought relief 2002 | F16: relief | G16: Rahat Kosh (the relief fund) | H16: Centre | I16: IN | J16: India-wide (Centre) | K16: NDA | M16: NCCF and early calamity-fund releases, free grain for relief work, fodder by rail; a Task Force under the Deputy PM | O16: ₹1,018 crore from the NCCF; ₹1,227 crore CRF share; 27.74 lakh tonnes of free grain | T16: Grain off-take under welfare schemes rose to 5.48 million tonnes in Apr–Oct 2002 from 3.15 million a year earlier. | V16: relief | W16: hrf003; hrf004 | X16: https://occult-kranti.github.io/fact-duel/hisaab/#/q/hrf003 https://occult-kranti.github.io/fact-duel/hisaab/#/q/hrf004 | Y16: Economic Survey 2002-03, ch. 8 (Agriculture) — Box 8.1: Drought relief measures | Z16: https://www.indiabudget.gov.in/budget_archive/es2002-03/chapt2003/chap83.pdf
A17: mz-intodelhna-2002 | B17: 2002 | D17: 2002 | E17: Mizoram Intodelhna Programme | F17: distribution | G17: Seedha Khaate Mein (straight into the account) | H17: State | I17: MZ | J17: Mizoram | K17: MNF | L17: Zoramthanga (Chief Minister, Mizoram, MNF) | M17: ₹11,000 per beneficiary family, replacing the old land-use scheme | N17: 53,288 families | T17: The MNF lost the 2008 election: the Congress won 32 of 40 on a new land-use promise. | V17: distribution | W17: hdb324 | X17: https://occult-kranti.github.io/fact-duel/hisaab/#/q/hdb324 | Y17: Frontline — Playing the Piper (27 Nov 2013) | Z17: https://frontline.thehindu.com/politics/playing-the-piper/article5389646.ece
A18: rj-drought-relief-2002 | B18: 2002 | D18: 2002 | E18: Drought relief works (Rajasthan, 2002–03) | F18: relief | G18: Rahat Kosh (the relief fund) | H18: State | I18: RJ | J18: Rajasthan | K18: INC | L18: Ashok Gehlot (Chief Minister, Rajasthan, INC) | M18: Relief work for vulnerable families (cut from 15 to 10 days a month); ₹60 daily wage claimed | O18: Centre paid ₹188.82 crore for 20.80 lakh BPL families; state need ₹1,530 crore | P18: Rajasthan Assembly 2003 | Q18: 2003-12 | S18: BJP won 120 of 200; Congress lost power | T18: Frontline found wages as low as ₹15 in places; the BJP won the December 2003 poll with 120 of 200 seats. | V18: pre-election; relief | W18: hrf103; hpe150 | X18: https://occult-kranti.github.io/fact-duel/hisaab/#/q/hrf103 https://occult-kranti.github.io/fact-duel/hisaab/#/q/hpe150 | Y18: Frontline — From bad to worse in Rajasthan (9 May 2003) | Z18: https://frontline.thehindu.com/the-nation/article30216871.ece
A19: hr-farm-power-dues-waiver-2002 | B19: 2002-04 | D19: 2002 | E19: Farm power-dues waiver (Haryana) | F19: distribution | G19: Seedha Khaate Mein (straight into the account) | H19: State | I19: HR | J19: Haryana | K19: INLD | L19: Om Prakash Chautala (Chief Minister, Haryana, INLD) | M19: 75% of each farmer’s pending power dues waived, after a full waiver was promised before the 2000 poll | T19: Farmers’ protests spread; police firings in May 2002 left three dead (Frontline). | V19: distribution; pre-election | W19: hpe100 | X19: https://occult-kranti.github.io/fact-duel/hisaab/#/q/hpe100 | Y19: Frontline — Farmer power (8 Jun 2002) | Z19: https://frontline.thehindu.com/other/article30245094.ece
A20: pb-free-farm-power-suspended-2002 | B20: 2002-10 | D20: 2002 | E20: Free farm power suspended (Punjab) | F20: distribution | G20: Seedha Khaate Mein (straight into the account) | H20: State | I20: PB | J20: Punjab | K20: INC | L20: Amarinder Singh (Chief Minister, Punjab, INC) | M20: Free electricity for all farmers, extended in 1997, discontinued from October 2002 | O20: ₹7,715 crore for farm power subsidy (2026-27) | T20: Restored in November 2005 and unbroken since 2007. | V20: distribution | W20: hdb100 | X20: https://occult-kranti.github.io/fact-duel/hisaab/#/q/hdb100 | Y20: The Indian Express — Power subsidy to social security: Parkash Singh Badal, the architect of populist schemes (26 Apr 2023) | Z20: https://indianexpress.com/article/cities/chandigarh/power-subsidy-social-security-architect-populist-schemes-8576206/
A21: mp-power-purchase-2003 | B21: 2003 | D21: 2003 | E21: Power purchase before the 2003 poll (MP) | F21: pre-election | G21: Chunav Se Pehle (before the vote) | H21: State | I21: MP | J21: Madhya Pradesh | K21: INC | L21: Digvijaya Singh (Chief Minister, Madhya Pradesh, INC) | M21: Electricity bought from other states amid a serious shortage | O21: ₹40–60 crore | P21: Madhya Pradesh Assembly 2003 | Q21: 2003-12 | S21: BJP won 173 of 230 seats; Congress 38 | T21: The BJP won 173 of 230 seats; the Congress fell to 38, ending ten years in power. | V21: pre-election | W21: hpe201 | X21: https://occult-kranti.github.io/fact-duel/hisaab/#/q/hpe201 | Y21: Rediff — 'The power situation in MP is serious' (31 May 2003) | Z21: https://www.rediff.com/news/interview/inter/20030531.htm
A22: tn-drought-aid-2003 | B22: 2003 | D22: 2003 | E22: Drought aid demand (Tamil Nadu) | F22: relief | G22: Rahat Kosh (the relief fund) | H22: State | I22: TN | J22: Tamil Nadu | K22: AIADMK | M22: At least ₹2,027 crore and 9 lakh tonnes of rice sought from the Centre | T22: The Centre had given ₹228 crore by early 2003, per the Kisan Sabha; the state put crop losses at ₹5,388 crore. | V22: relief | W22: hrf104 | X22: https://occult-kranti.github.io/fact-duel/hisaab/#/q/hrf104 | Y22: Frontline — A worsening drought (28 Feb 2003) | Z22: https://frontline.thehindu.com/other/article30215779.ece
A23: in-antyodaya-expansion-2003 | B23: 2003-02 | D23: 2003 | E23: Antyodaya expanded (Budget 2003-04) | F23: distribution | G23: Seedha Khaate Mein (straight into the account) | H23: Centre | I23: IN | J23: India-wide (Centre) | K23: NDA | L23: Jaswant Singh (Union Finance Minister, BJP) | M23: Antyodaya grain for 50 lakh more families from 1 April 2003 | O23: ₹507 crore extra | T23: AAY covered 1.5 crore families by early 2004. | V23: distribution | W23: hdb003 | X23: https://occult-kranti.github.io/fact-duel/hisaab/#/q/hdb003 | Y23: indiabudget.gov.in — Budget Speech 2003-04, Jaswant Singh (Feb 2003) | Z23: https://www.indiabudget.gov.in/budget_archive/ub2003-04/bs/speecha.htm
A24: in-nccd-crude-2003 | B24: 2003-02 | D24: 2003 | E24: Calamity duty on crude oil | F24: relief | G24: Rahat Kosh (the relief fund) | H24: Centre | I24: IN | J24: India-wide (Centre) | K24: NDA | L24: Jaswant Singh (Union Finance Minister, BJP) | M24: NCCD of ₹50 a tonne on crude and 1% on yarn and vehicles, ‘limited to one year only’, after the 2002 drought | T24: Still levied on domestic crude in January 2026, over two decades on; the oil industry asked for its removal. | V24: relief | W24: hrf005 | X24: https://occult-kranti.github.io/fact-duel/hisaab/#/q/hrf005 | Y24: Economic Times — Budget 2026: Oil industry seeks abolition or review of OID cess (15 Jan 2026) | Z24: https://economictimes.indiatimes.com/industry/energy/oil-gas/budget-2026-oil-industry-seeks-abolition-or-review-of-oid-cess-on-pre-nelp-and-nomination-blocks/articleshow/126545404.cms
A25: in-universal-health-insurance-2003 | B25: 2003-02 | D25: 2003 | E25: Universal Health Insurance Scheme | F25: distribution | G25: Seedha Khaate Mein (straight into the account) | H25: Centre | I25: IN | J25: India-wide (Centre) | K25: NDA | L25: Jaswant Singh (Union Finance Minister, BJP) | M25: Hospital cover up to ₹30,000 for ₹1 a day; the Centre paid ₹100 a year of a BPL family’s premium | T25: Only 11,408 BPL families had joined by May 2004; the UPA limited it to BPL families and raised the subsidy. | V25: distribution | W25: hdb004 | X25: https://occult-kranti.github.io/fact-duel/hisaab/#/q/hdb004 | Y25: indiabudget.gov.in — Budget Speech 2003-04, Jaswant Singh (Feb 2003) | Z25: https://www.indiabudget.gov.in/budget_archive/ub2003-04/bs/speecha.htm
A26: ap-mahanadu-farm-package-2003 | B26: 2003-05 | D26: 2003 | E26: Naidu's Mahanadu farm package | F26: pre-election | G26: Chunav Se Pehle (before the vote) | H26: State | I26: AP | J26: Andhra Pradesh | K26: TDP | L26: N. Chandrababu Naidu (Chief Minister, Andhra Pradesh, TDP) | M26: ₹15,000 grant plus ₹2,500 micro-credit per farmer self-help group; interest waivers on drought-hit co-op loans | O26: ₹250 crore interest waiver + ₹94 crore penal-interest waiver | P26: Andhra Pradesh Assembly 2004 | Q26: 2004-04 | R26: 328 | S26: Congress won 185 of 294 seats; TDP 47 | T26: Congress won 185 of 294 seats in April 2004; the TDP fell to 47. | V26: distribution; pre-election | W26: hdb201 | X26: https://occult-kranti.github.io/fact-duel/hisaab/#/q/hdb201 | Y26: Times of India — Naidu's major sops for farmers (29 May 2003) | Z26: https://timesofindia.indiatimes.com/city/hyderabad/naidus-major-sops-for-farmers/articleshow/47811599.cms
A27: ka-yeshasvini-2003 | B27: 2003-06 | D27: 2003 | E27: Yeshasvini farmers’ health scheme | F27: distribution | G27: Seedha Khaate Mein (straight into the account) | H27: State | I27: KA | J27: Karnataka | K27: INC | L27: S.M. Krishna (Chief Minister, Karnataka, INC) | M27: Surgery at 74 listed hospitals for a ₹5-a-month premium | T27: 250 surgeries in the first 27 days; ₹14.25 crore collected (TOI, June 2003). | V27: distribution | W27: hdb402 | X27: https://occult-kranti.github.io/fact-duel/hisaab/#/q/hdb402 | Y27: The Times of India — Krishna moots Yeshasvini scheme for other sectors (29 Jun 2003) | Z27: https://timesofindia.indiatimes.com/city/bengaluru/krishna-moots-yeshasvini-scheme-for-other-sectors/articleshow/49404.cms
A28: in-india-shining-ads-2004 | B28: 2004 | D28: 2004 | E28: ‘India Shining’ government ads | F28: pre-election | G28: Chunav Se Pehle (before the vote) | H28: Centre | I28: IN | J28: India-wide (Centre) | K28: NDA | M28: A government-funded advertising campaign | O28: ₹65 crore | P28: Lok Sabha 2004 | Q28: 2004-04 | S28: INC 145, BJP 138 seats; the Congress-led UPA formed the government | T28: The EC barred its broadcast until polling ended; the NDA lost office (Congress 145, BJP 138). | V28: pre-election | W28: hpe001 | X28: https://occult-kranti.github.io/fact-duel/hisaab/#/q/hpe001 | Y28: Rediff (Reuters) — The man behind 'India Shining' slogan (2 Apr 2004) | Z28: https://www.rediff.com/business/special/shining/20040402.htm
A29: ka-farm-distress-compensation-2004 | B29: 2004 | D29: 2004 | E29: Farm-distress compensation (Karnataka) | F29: relief | G29: Rahat Kosh (the relief fund) | H29: State | I29: KA | J29: Karnataka | K29: INC | L29: S.M. Krishna (Chief Minister, Karnataka, INC) | M29: ₹1 lakh to families of indebted farmers who died by suicide | P29: Karnataka Assembly 2004 | Q29: 2004-04 | S29: Hung: BJP 79, Congress 65, JD(S) 58 of 224 | T29: Barely 10% of needy families were paid, Frontline found; the poll gave a hung House (BJP 79, Congress 65, JD(S) 58). | V29: pre-election; relief | W29: hpe102 | X29: https://occult-kranti.github.io/fact-duel/hisaab/#/q/hpe102 | Y29: Frontline — The rural anger in Karnataka (18 Jun 2004) | Z29: https://frontline.thehindu.com/cover-story/article30223009.ece
A30: in-mini-budget-2004 | B30: 2004-01 | D30: 2004 | E30: Jaswant Singh’s ‘mini-budget’ | F30: pre-election | G30: Chunav Se Pehle (before the vote) | H30: Centre | I30: IN | J30: India-wide (Centre) | K30: NDA | L30: Jaswant Singh (Union Finance Minister, BJP) | M30: Customs cuts on phones, IT and electronics; travel tax abolished | P30: Lok Sabha 2004 | Q30: 2004-04 | R30: 103 | S30: INC 145, BJP 138 seats; the Congress-led UPA formed the government | T30: Polling began 103 days later; the NDA lost office as the Congress won 145 seats to the BJP’s 138. | V30: pre-election | W30: hpe002 | X30: https://occult-kranti.github.io/fact-duel/hisaab/#/q/hpe002 | Y30: Rediff — Markets likely to zoom up on Friday (8 Jan 2004) | Z30: https://www.rediff.com/business/report/bud12/20040108.htm
A31: in-antyodaya-expansion-2004 | B31: 2004-02 | D31: 2004 | E31: Antyodaya expanded to 2 crore families (interim budget) | F31: pre-election | G31: Chunav Se Pehle (before the vote) | H31: Centre | I31: IN | J31: India-wide (Centre) | K31: NDA | L31: Jaswant Singh (Union Finance Minister, BJP) | M31: Antyodaya extended to 2 crore BPL families from 1 April 2004 | P31: Lok Sabha 2004 | Q31: 2004-04 | R31: 77 | S31: INC 145, BJP 138 seats; the Congress-led UPA formed the government | T31: The NDA lost the poll; the UPA kept the expansion (subsidy near ₹3,500 crore) and took AAY to 2.5 crore households in 2005. | V31: distribution; pre-election | W31: hdb005 | X31: https://occult-kranti.github.io/fact-duel/hisaab/#/q/hdb005 | Y31: indiabudget.gov.in — Interim Budget Speech 2004-05, Jaswant Singh (3 Feb 2004) | Z31: https://www.indiabudget.gov.in/budget_archive/ub2004-05(I)/bs/speecha.htm
A32: in-da-merger-2004 | B32: 2004-02 | D32: 2004 | E32: DA merged into basic pay (interim budget) | F32: pre-election | G32: Chunav Se Pehle (before the vote) | H32: Centre | I32: IN | J32: India-wide (Centre) | K32: NDA | L32: Jaswant Singh (Union Finance Minister, BJP) | M32: Dearness allowance up to 50% of pay merged into basic pay for central staff; ₹25,000 crore defence fund | P32: Lok Sabha 2004 | Q32: 2004-04 | R32: 77 | S32: INC 145, BJP 138 seats; the Congress-led UPA formed the government | T32: Polling began 77 days later; the NDA left office. | V32: pre-election | W32: hpe003 | X32: https://occult-kranti.github.io/fact-duel/hisaab/#/q/hpe003 | Y32: indiabudget.gov.in — Interim Budget 2004-05 speech, Jaswant Singh (3 Feb 2004) | Z32: https://www.indiabudget.gov.in/budget_archive/ub2004-05(I)/bs/speecha.htm
A33: in-farm-income-insurance-2004 | B33: 2004-02 | D33: 2004 | E33: Farm Income Insurance Scheme extended | F33: pre-election | G33: Chunav Se Pehle (before the vote) | H33: Centre | I33: IN | J33: India-wide (Centre) | K33: NDA | L33: Jaswant Singh (Union Finance Minister, BJP) | M33: Pilot extended from 20 to 100 districts; Kisan Credit Cards for all eligible farmers | P33: Lok Sabha 2004 | Q33: 2004-04 | R33: 77 | S33: INC 145, BJP 138 seats; the Congress-led UPA formed the government | T33: The pilot was discontinued in 2004 after the NDA lost the poll. | V33: pre-election | W33: hpe005 | X33: https://occult-kranti.github.io/fact-duel/hisaab/#/q/hpe005 | Y33: indiabudget.gov.in — Interim Budget 2004-05 speech, Jaswant Singh (3 Feb 2004) | Z33: https://www.indiabudget.gov.in/budget_archive/ub2004-05(I)/bs/speecha.htm
A34: in-pmssy-aiims-2004 | B34: 2004-02 | D34: 2004 | E34: Six AIIMS-like hospitals (PMSSY) | F34: pre-election | G34: Chunav Se Pehle (before the vote) | H34: Centre | I34: IN | J34: India-wide (Centre) | K34: NDA | L34: Atal Bihari Vajpayee (Prime Minister, BJP); Jaswant Singh (Union Finance Minister, BJP) | M34: Six AIIMS-like institutes at Bhopal, Bhubaneswar, Jodhpur, Patna, Raipur and Rishikesh | P34: Lok Sabha 2004 | Q34: 2004-04 | R34: 77 | S34: INC 145, BJP 138 seats; the Congress-led UPA formed the government | T34: The UPA Cabinet approved them in 2006 and MBBS classes began in 2012; a 2019 CAG report found infrastructure still pending. | V34: pre-election | W34: hpe004 | X34: https://occult-kranti.github.io/fact-duel/hisaab/#/q/hpe004 | Y34: Alt News — Did UPA govt build only one AIIMS during their tenure? (25 Apr 2021) | Z34: https://www.altnews.in/did-upa-govt-build-only-one-aiims-institute-during-their-tenure-false-claim-viral/
A35: ap-free-farm-power-2004 | B35: 2004-05 | D35: 2004 | E35: Free farm power and bill waiver (Andhra Pradesh) | F35: distribution | G35: Seedha Khaate Mein (straight into the account) | H35: State | I35: AP | J35: Andhra Pradesh | K35: INC | L35: Y.S. Rajasekhara Reddy (Chief Minister, Andhra Pradesh, INC) | M35: Free power for all farmers plus a waiver of unpaid farm power bills, signed on oath day | O35: Up to ₹436 crore in 2004-05, plus ₹1,192 crore of waived dues | T35: YSR said free power would continue while the Congress held office; the Congress was re-elected in 2009 with 156 of 294 seats. | V35: distribution | W35: hdb202 | X35: https://occult-kranti.github.io/fact-duel/hisaab/#/q/hdb202 | Y35: Times of India — Farmers to get free power (15 May 2004) | Z35: https://timesofindia.indiatimes.com/city/hyderabad/farmers-to-get-free-power/articleshow/676611.cms
A36: tn-power-tariff-rollback-2004 | B36: 2004-05 | D36: 2004 | E36: Domestic power tariff rollback (Tamil Nadu) | F36: distribution | G36: Seedha Khaate Mein (straight into the account) | H36: State | I36: TN | J36: Tamil Nadu | K36: AIADMK | L36: J. Jayalalithaa (Chief Minister, Tamil Nadu, AIADMK) | M36: Household power bills cut back to December 2001 rates | N36: Nearly 1.2 crore families | O36: ₹910 crore a year | T36: Came weeks after the DMK-led alliance swept all 39 Lok Sabha seats; paid to the TNEB as a budget subsidy. | V36: distribution | W36: hdb204 | X36: https://occult-kranti.github.io/fact-duel/hisaab/#/q/hdb204 | Y36: Times of India — Jaya on a roll: Power rates go back 2 yrs (1 Jun 2004) | Z36: https://timesofindia.indiatimes.com/india/jaya-on-a-roll-power-rates-go-back-2-yrs/articleshow/711517.cms
A37: br-floods-crf-2004 | B37: 2004-07 | D37: 2004 | E37: Bihar floods: Calamity Relief Fund release | F37: relief | G37: Rahat Kosh (the relief fund) | H37: State | I37: BR | J37: Bihar | K37: RJD | M37: First instalment of Bihar’s ₹81.8 crore CRF held up; ₹30.525 crore released on 12 July | N37: Over a crore people in 16 districts affected (unconfirmed reports) | T37: The release was delayed because the state had not filed its 2003-04 utilisation report; an inter-ministerial team assessed damage later. | V37: relief | W37: hrf202 | X37: https://occult-kranti.github.io/fact-duel/hisaab/#/q/hrf202 | Y37: Frontline — Battling Bihar (13 Aug 2004) | Z37: https://frontline.thehindu.com/other/article30223930.ece
A38: in-food-for-work-2004 | B38: 2004-07 | D38: 2004 | E38: National Food for Work Programme | F38: distribution | G38: Seedha Khaate Mein (straight into the account) | H38: Centre | I38: IN | J38: India-wide (Centre) | K38: UPA | L38: P. Chidambaram (Union Finance Minister, INC) | M38: Food-for-work in the 150 most backward districts pending a jobs-guarantee law | O38: Over ₹6,000 crore pooled from existing schemes | T38: The promised guarantee law, NREGA, was enacted in 2005 and rolled out in February 2006. | V38: distribution | W38: hdb006 | X38: https://occult-kranti.github.io/fact-duel/hisaab/#/q/hdb006 | Y38: indiabudget.gov.in — Budget Speech 2004-05, P. Chidambaram (8 Jul 2004) | Z38: https://www.indiabudget.gov.in/budget_archive/ub2004-05/bs/speecha.htm
A39: mh-free-farm-power-2004 | B39: 2004-08 | D39: 2004 | E39: Free farm power before the 2004 poll (Maharashtra) | F39: pre-election | G39: Chunav Se Pehle (before the vote) | H39: State | I39: MH | J39: Maharashtra | K39: INC | L39: Sushilkumar Shinde (Chief Minister, Maharashtra, INC) | M39: Free power for farmers, sought only from July 2004 to March 2005 | N39: Over 23 lakh farmers | O39: ₹1,590 crore subsidy | P39: Maharashtra Assembly 2004 | Q39: 2004-10 | R39: 70 | S39: Congress–NCP front retained power: NCP 71, Congress 69 of 288 seats | T39: The Congress–NCP front kept power; its March 2005 budget said it would reconsider this ‘pre-election promise’. | V39: distribution; pre-election | W39: hdb203 | X39: https://occult-kranti.github.io/fact-duel/hisaab/#/q/hdb203 | Y39: Times of India — Free power for farmers only up to March? (16 Aug 2004) | Z39: https://timesofindia.indiatimes.com/city/pune/free-power-for-farmers-only-up-to-march/articleshow/816832.cms
A40: hr-old-age-allowance-2004 | B40: 2004-11 | D40: 2004 | E40: Old Age Samman Allowance raised to ₹300 | F40: pre-election | G40: Chunav Se Pehle (before the vote) | H40: State | I40: HR | J40: Haryana | K40: INLD | L40: Om Prakash Chautala (Chief Minister, Haryana, INLD) | M40: Old-age allowance raised from ₹200 to ₹300 a month | P40: Haryana Assembly 2005 | Q40: 2005-02 | R40: 94 | S40: Congress won 67 of 90 seats; INLD 9 | T40: The INLD lost the February 2005 poll: the Congress won 67 of 90 seats and the INLD fell to 9. | V40: distribution; pre-election | W40: hdb101 | X40: https://occult-kranti.github.io/fact-duel/hisaab/#/q/hdb101 | Y40: Government of Haryana, Social Justice & Empowerment — Old Age Samman Allowance Scheme (rate history, updated Jul 2026) | Z40: https://socialjusticehry.gov.in/old-age-samman-allowance-scheme/
...

Sheet By year
A1: Year | B1: Seedha Khaate Mein (distribution) | C1: Rahat Kosh (relief) | D1: Chunav Se Pehle (pre-election) | E1: All measures | F1: Centre | G1: State | H1: Named the poll it preceded
A2: 2000 | B2: =COUNTIFS(Ledger!$D$2:$D$390,$A2,Ledger!$F$2:$F$390,"distribution") -> 2 | C2: =COUNTIFS(Ledger!$D$2:$D$390,$A2,Ledger!$F$2:$F$390,"relief") -> 3 | D2: =COUNTIFS(Ledger!$D$2:$D$390,$A2,Ledger!$F$2:$F$390,"pre-election") -> 1 | E2: =SUM(B2:D2) -> 6 | F2: =COUNTIFS(Ledger!$D$2:$D$390,$A2,Ledger!$H$2:$H$390,"Centre") -> 4 | G2: =COUNTIFS(Ledger!$D$2:$D$390,$A2,Ledger!$H$2:$H$390,"State") -> 2 | H2: =COUNTIFS(Ledger!$D$2:$D$390,$A2,Ledger!$P$2:$P$390,"<>") -> 1
A3: 2001 | B3: =COUNTIFS(Ledger!$D$2:$D$390,$A3,Ledger!$F$2:$F$390,"distribution") -> 3 | C3: =COUNTIFS(Ledger!$D$2:$D$390,$A3,Ledger!$F$2:$F$390,"relief") -> 3 | D3: =COUNTIFS(Ledger!$D$2:$D$390,$A3,Ledger!$F$2:$F$390,"pre-election") -> 0 | E3: =SUM(B3:D3) -> 6 | F3: =COUNTIFS(Ledger!$D$2:$D$390,$A3,Ledger!$H$2:$H$390,"Centre") -> 3 | G3: =COUNTIFS(Ledger!$D$2:$D$390,$A3,Ledger!$H$2:$H$390,"State") -> 3 | H3: =COUNTIFS(Ledger!$D$2:$D$390,$A3,Ledger!$P$2:$P$390,"<>") -> 0
A4: 2002 | B4: =COUNTIFS(Ledger!$D$2:$D$390,$A4,Ledger!$F$2:$F$390,"distribution") -> 4 | C4: =COUNTIFS(Ledger!$D$2:$D$390,$A4,Ledger!$F$2:$F$390,"relief") -> 3 | D4: =COUNTIFS(Ledger!$D$2:$D$390,$A4,Ledger!$F$2:$F$390,"pre-election") -> 0 | E4: =SUM(B4:D4) -> 7 | F4: =COUNTIFS(Ledger!$D$2:$D$390,$A4,Ledger!$H$2:$H$390,"Centre") -> 1 | G4: =COUNTIFS(Ledger!$D$2:$D$390,$A4,Ledger!$H$2:$H$390,"State") -> 6 | H4: =COUNTIFS(Ledger!$D$2:$D$390,$A4,Ledger!$P$2:$P$390,"<>") -> 1
A5: 2003 | B5: =COUNTIFS(Ledger!$D$2:$D$390,$A5,Ledger!$F$2:$F$390,"distribution") -> 3 | C5: =COUNTIFS(Ledger!$D$2:$D$390,$A5,Ledger!$F$2:$F$390,"relief") -> 2 | D5: =COUNTIFS(Ledger!$D$2:$D$390,$A5,Ledger!$F$2:$F$390,"pre-election") -> 2 | E5: =SUM(B5:D5) -> 7 | F5: =COUNTIFS(Ledger!$D$2:$D$390,$A5,Ledger!$H$2:$H$390,"Centre") -> 3 | G5: =COUNTIFS(Ledger!$D$2:$D$390,$A5,Ledger!$H$2:$H$390,"State") -> 4 | H5: =COUNTIFS(Ledger!$D$2:$D$390,$A5,Ledger!$P$2:$P$390,"<>") -> 2
A6: 2004 | B6: =COUNTIFS(Ledger!$D$2:$D$390,$A6,Ledger!$F$2:$F$390,"distribution") -> 3 | C6: =COUNTIFS(Ledger!$D$2:$D$390,$A6,Ledger!$F$2:$F$390,"relief") -> 3 | D6: =COUNTIFS(Ledger!$D$2:$D$390,$A6,Ledger!$F$2:$F$390,"pre-election") -> 8 | E6: =SUM(B6:D6) -> 14 | F6: =COUNTIFS(Ledger!$D$2:$D$390,$A6,Ledger!$H$2:$H$390,"Centre") -> 8 | G6: =COUNTIFS(Ledger!$D$2:$D$390,$A6,Ledger!$H$2:$H$390,"State") -> 6 | H6: =COUNTIFS(Ledger!$D$2:$D$390,$A6,Ledger!$P$2:$P$390,"<>") -> 9
A7: 2005 | B7: =COUNTIFS(Ledger!$D$2:$D$390,$A7,Ledger!$F$2:$F$390,"distribution") -> 3 | C7: =COUNTIFS(Ledger!$D$2:$D$390,$A7,Ledger!$F$2:$F$390,"relief") -> 6 | D7: =COUNTIFS(Ledger!$D$2:$D$390,$A7,Ledger!$F$2:$F$390,"pre-election") -> 1 | E7: =SUM(B7:D7) -> 10 | F7: =COUNTIFS(Ledger!$D$2:$D$390,$A7,Ledger!$H$2:$H$390,"Centre") -> 4 | G7: =COUNTIFS(Ledger!$D$2:$D$390,$A7,Ledger!$H$2:$H$390,"State") -> 6 | H7: =COUNTIFS(Ledger!$D$2:$D$390,$A7,Ledger!$P$2:$P$390,"<>") -> 1
A8: 2006 | B8: =COUNTIFS(Ledger!$D$2:$D$390,$A8,Ledger!$F$2:$F$390,"distribution") -> 5 | C8: =COUNTIFS(Ledger!$D$2:$D$390,$A8,Ledger!$F$2:$F$390,"relief") -> 1 | D8: =COUNTIFS(Ledger!$D$2:$D$390,$A8,Ledger!$F$2:$F$390,"pre-election") -> 0 | E8: =SUM(B8:D8) -> 6 | F8: =COUNTIFS(Ledger!$D$2:$D$390,$A8,Ledger!$H$2:$H$390,"Centre") -> 1 | G8: =COUNTIFS(Ledger!$D$2:$D$390,$A8,Ledger!$H$2:$H$390,"State") -> 5 | H8: =COUNTIFS(Ledger!$D$2:$D$390,$A8,Ledger!$P$2:$P$390,"<>") -> 0
A9: 2007 | B9: =COUNTIFS(Ledger!$D$2:$D$390,$A9,Ledger!$F$2:$F$390,"distribution") -> 3 | C9: =COUNTIFS(Ledger!$D$2:$D$390,$A9,Ledger!$F$2:$F$390,"relief") -> 1 | D9: =COUNTIFS(Ledger!$D$2:$D$390,$A9,Ledger!$F$2:$F$390,"pre-election") -> 0 | E9: =SUM(B9:D9) -> 4 | F9: =COUNTIFS(Ledger!$D$2:$D$390,$A9,Ledger!$H$2:$H$390,"Centre") -> 1 | G9: =COUNTIFS(Ledger!$D$2:$D$390,$A9,Ledger!$H$2:$H$390,"State") -> 3 | H9: =COUNTIFS(Ledger!$D$2:$D$390,$A9,Ledger!$P$2:$P$390,"<>") -> 0
A10: 2008 | B10: =COUNTIFS(Ledger!$D$2:$D$390,$A10,Ledger!$F$2:$F$390,"distribution") -> 1 | C10: =COUNTIFS(Ledger!$D$2:$D$390,$A10,Ledger!$F$2:$F$390,"relief") -> 1 | D10: =COUNTIFS(Ledger!$D$2:$D$390,$A10,Ledger!$F$2:$F$390,"pre-election") -> 11 | E10: =SUM(B10:D10) -> 13 | F10: =COUNTIFS(Ledger!$D$2:$D$390,$A10,Ledger!$H$2:$H$390,"Centre") -> 6 | G10: =COUNTIFS(Ledger!$D$2:$D$390,$A10,Ledger!$H$2:$H$390,"State") -> 7 | H10: =COUNTIFS(Ledger!$D$2:$D$390,$A10,Ledger!$P$2:$P$390,"<>") -> 11
A11: 2009 | B11: =COUNTIFS(Ledger!$D$2:$D$390,$A11,Ledger!$F$2:$F$390,"distribution") -> 2 | C11: =COUNTIFS(Ledger!$D$2:$D$390,$A11,Ledger!$F$2:$F$390,"relief") -> 4 | D11: =COUNTIFS(Ledger!$D$2:$D$390,$A11,Ledger!$F$2:$F$390,"pre-election") -> 4 | E11: =SUM(B11:D11) -> 10 | F11: =COUNTIFS(Ledger!$D$2:$D$390,$A11,Ledger!$H$2:$H$390,"Centre") -> 3 | G11: =COUNTIFS(Ledger!$D$2:$D$390,$A11,Ledger!$H$2:$H$390,"State") -> 7 | H11: =COUNTIFS(Ledger!$D$2:$D$390,$A11,Ledger!$P$2:$P$390,"<>") -> 4
A12: 2010 | B12: =COUNTIFS(Ledger!$D$2:$D$390,$A12,Ledger!$F$2:$F$390,"distribution") -> 2 | C12: =COUNTIFS(Ledger!$D$2:$D$390,$A12,Ledger!$F$2:$F$390,"relief") -> 2 | D12: =COUNTIFS(Ledger!$D$2:$D$390,$A12,Ledger!$F$2:$F$390,"pre-election") -> 0 | E12: =SUM(B12:D12) -> 4 | F12: =COUNTIFS(Ledger!$D$2:$D$390,$A12,Ledger!$H$2:$H$390,"Centre") -> 2 | G12: =COUNTIFS(Ledger!$D$2:$D$390,$A12,Ledger!$H$2:$H$390,"State") -> 2 | H12: =COUNTIFS(Ledger!$D$2:$D$390,$A12,Ledger!$P$2:$P$390,"<>") -> 0
A13: 2011 | B13: =COUNTIFS(Ledger!$D$2:$D$390,$A13,Ledger!$F$2:$F$390,"distribution") -> 5 | C13: =COUNTIFS(Ledger!$D$2:$D$390,$A13,Ledger!$F$2:$F$390,"relief") -> 1 | D13: =COUNTIFS(Ledger!$D$2:$D$390,$A13,Ledger!$F$2:$F$390,"pre-election") -> 3 | E13: =SUM(B13:D13) -> 9 | F13: =COUNTIFS(Ledger!$D$2:$D$390,$A13,Ledger!$H$2:$H$390,"Centre") -> 2 | G13: =COUNTIFS(Ledger!$D$2:$D$390,$A13,Ledger!$H$2:$H$390,"State") -> 7 | H13: =COUNTIFS(Ledger!$D$2:$D$390,$A13,Ledger!$P$2:$P$390,"<>") -> 3
... A28: 2026 | B28: =COUNTIFS(Ledger!$D$2:$D$390,$A28,Ledger!$F$2:$F$390,"distribution") -> 10 | C28: =COUNTIFS(Ledger!$D$2:$D$390,$A28,Ledger!$F$2:$F$390,"relief") -> 1 | D28: =COUNTIFS(Ledger!$D$2:$D$390,$A28,Ledger!$F$2:$F$390,"pre-election") -> 7 | E28: =SUM(B28:D28) -> 18 | F28: =COUNTIFS(Ledger!$D$2:$D$390,$A28,Ledger!$H$2:$H$390,"Centre") -> 2 | G28: =COUNTIFS(Ledger!$D$2:$D$390,$A28,Ledger!$H$2:$H$390,"State") -> 16 | H28: =COUNTIFS(Ledger!$D$2:$D$390,$A28,Ledger!$P$2:$P$390,"<>") -> 7
A29: Total | B29: =SUM(B2:B28) -> 137 | C29: =SUM(C2:C28) -> 95 | D29: =SUM(D2:D28) -> 157 | E29: =SUM(E2:E28) -> 389 | F29: =SUM(F2:F28) -> 128 | G29: =SUM(G2:G28) -> 261 | H29: =SUM(H2:H28) -> 164
A31: Check | B31: =COUNTA(Ledger!$A$2:$A$390) -> 389 | C31: rows on the Ledger sheet; equals the All measures total above.
